async function logic (x) {
  try {
       const y = await (y) => (y + 1)
       const y2 = await (y2) => (y2 + 1)
       ...
  } catch(e) {
     console.log('Error handling ..', e)
  }
}
